// let a;
// console.log(a.length);

// console.log("This line will not be printed as we have exception/error in above line");


// using try catch block

try {
    let a;
    console.log(a.length);
    console.log("Inside try block");
}
catch (e) {
    console.log(["Inside catch block", e]);
}

console.log("Hello everyone");


